<?xml version="1.0" encoding="utf-8"?>
<!-- This URDF was automatically created by SolidWorks to URDF Exporter! Originally created by Stephen Brawner (brawner@gmail.com) 
     Commit Version: 1.6.0-1-g15f4949  Build Version: 1.6.7594.29634
     For more information, please see http://wiki.ros.org/sw_urdf_exporter -->
<robot
  name="two_wheeled_robot">
  <link
    name="base_link">
    <inertial>
      <origin
        xyz="-1.4387E-05 1.9847E-17 0.060106"
        rpy="0 0 0" />
      <mass
        value="12.812" />
      <inertia
        ixx="0.12262"
        ixy="2.6963E-18"
        ixz="-7.5972E-06"
        iyy="0.045704"
        iyz="-1.1294E-18"
        izz="0.16644" />
    </inertial>
    <visual>
      <origin
        xyz="0 0 0"
        rpy="0 0 0" />
      <geometry>
        <mesh
          filename="package://two_wheeled_robot/meshes/base_link.STL" />
      </geometry>
      <material
        name="">
        <color
          rgba="0.89804 0.91765 0.92941 1" />
      </material>
    </visual>
    <collision>
      <origin
        xyz="0 0 0"
        rpy="0 0 0" />
      <geometry>
        <mesh
          filename="package://two_wheeled_robot/meshes/base_link.STL" />
      </geometry>
    </collision>
  </link>
  <link
    name="lw_Link">
    <inertial>
      <origin
        xyz="1.0458E-06 2.5494E-06 -0.0072499"
        rpy="0 0 0" />
      <mass
        value="4.809" />
      <inertia
        ixx="0.022657"
        ixy="-2.0596E-09"
        ixz="3.9168E-08"
        iyy="0.022657"
        iyz="9.5141E-08"
        izz="0.033315" />
    </inertial>
    <visual>
      <origin
        xyz="0 0 0"
        rpy="0 0 0" />
      <geometry>
        <mesh
          filename="package://two_wheeled_robot/meshes/lw_Link.STL" />
      </geometry>
      <material
        name="">
        <color
          rgba="0.29804 0.29804 0.29804 1" />
      </material>
    </visual>
    <collision>
      <origin
        xyz="0 0 0"
        rpy="0 0 0" />
      <geometry>
        <mesh
          filename="package://two_wheeled_robot/meshes/lw_Link.STL" />
      </geometry>
    </collision>
  </link>
  <joint
    name="lw_joint"
    type="continuous">
    <origin
      xyz="0.00080677 0.27524 -0.05"
      rpy="-1.5708 0 0" />
    <parent
      link="base_link" />
    <child
      link="lw_Link" />
    <axis
      xyz="0 0 -1" />
  </joint>
  <link
    name="rw_Link">
    <inertial>
      <origin
        xyz="-5.9399E-07 2.6908E-06 -0.0071869"
        rpy="0 0 0" />
      <mass
        value="4.809" />
      <inertia
        ixx="0.022657"
        ixy="2.0187E-09"
        ixz="-2.2054E-08"
        iyy="0.022657"
        iyz="1.005E-07"
        izz="0.033315" />
    </inertial>
    <visual>
      <origin
        xyz="0 0 0"
        rpy="0 0 0" />
      <geometry>
        <mesh
          filename="package://two_wheeled_robot/meshes/rw_Link.STL" />
      </geometry>
      <material
        name="">
        <color
          rgba="0.29804 0.29804 0.29804 1" />
      </material>
    </visual>
    <collision>
      <origin
        xyz="0 0 0"
        rpy="0 0 0" />
      <geometry>
        <mesh
          filename="package://two_wheeled_robot/meshes/rw_Link.STL" />
      </geometry>
    </collision>
  </link>
  <joint
    name="rw_joint"
    type="continuous">
    <origin
      xyz="0.00080677 -0.27524 -0.05"
      rpy="1.5708 0 0" />
    <parent
      link="base_link" />
    <child
      link="rw_Link" />
    <axis
      xyz="0 0 1" />
  </joint>
  <link
    name="cws_Link">
    <inertial>
      <origin
        xyz="-0.0039596 -8.3176E-05 -0.041094"
        rpy="0 0 0" />
      <mass
        value="1.586" />
      <inertia
        ixx="0.0015127"
        ixy="3.4421E-07"
        ixz="-1.8122E-05"
        iyy="0.0020985"
        iyz="1.6261E-07"
        izz="0.0013004" />
    </inertial>
    <visual>
      <origin
        xyz="0 0 0"
        rpy="0 0 0" />
      <geometry>
        <mesh
          filename="package://two_wheeled_robot/meshes/cws_Link.STL" />
      </geometry>
      <material
        name="">
        <color
          rgba="0.75294 0.75294 0.75294 1" />
      </material>
    </visual>
    <collision>
      <origin
        xyz="0 0 0"
        rpy="0 0 0" />
      <geometry>
        <mesh
          filename="package://two_wheeled_robot/meshes/cws_Link.STL" />
      </geometry>
    </collision>
  </link>
  <joint
    name="cws_joint"
    type="continuous">
    <origin
      xyz="0.10215 0 -0.072"
      rpy="0 0 0" />
    <parent
      link="base_link" />
    <child
      link="cws_Link" />
    <axis
      xyz="0 0 1" />
  </joint>
  <link
    name="lidar_Link">
    <inertial>
      <origin
        xyz="0.0023743 8.0583E-05 0.019972"
        rpy="0 0 0" />
      <mass
        value="0.56987" />
      <inertia
        ixx="0.00029196"
        ixy="-2.1729E-06"
        ixz="7.5625E-07"
        iyy="0.0003559"
        iyz="2.5667E-08"
        izz="0.00050128" />
    </inertial>
    <visual>
      <origin
        xyz="0 0 0"
        rpy="0 0 0" />
      <geometry>
        <mesh
          filename="package://two_wheeled_robot/meshes/lidar_Link.STL" />
      </geometry>
      <material
        name="">
        <color
          rgba="0.89804 0.91765 0.92941 1" />
      </material>
    </visual>
    <collision>
      <origin
        xyz="0 0 0"
        rpy="0 0 0" />
      <geometry>
        <mesh
          filename="package://two_wheeled_robot/meshes/lidar_Link.STL" />
      </geometry>
    </collision>
  </link>
  <joint
    name="lidar_joint"
    type="fixed">
    <origin
      xyz="0 0 0.23"
      rpy="0 0 0" />
    <parent
      link="base_link" />
    <child
      link="lidar_Link" />
    <axis
      xyz="0 0 0" />
  </joint>
</robot>