<?xml version="1.0" encoding="utf-8"?>
<!-- This URDF was automatically created by SolidWorks to URDF Exporter! Originally created by Stephen Brawner (brawner@gmail.com) 
     Commit Version: 1.6.0-1-g15f4949  Build Version: 1.6.7594.29634
     For more information, please see http://wiki.ros.org/sw_urdf_exporter -->
<robot
  name="urdf_assem_final">
  <link
    name="base_link">
    <inertial>
      <origin
        xyz="-1.55905843790549E-09 8.35996216697055E-10 0.227427844138389"
        rpy="0 0 0" />
      <mass
        value="13.4118986785811" />
      <inertia
        ixx="0.138795528767983"
        ixy="6.1031384950179E-09"
        ixz="-2.54609804268592E-10"
        iyy="0.057261428895309"
        iyz="5.70138502164683E-10"
        izz="0.191099141268272" />
    </inertial>
    <visual>
      <origin
        xyz="0 0 0"
        rpy="0 0 0" />
      <geometry>
        <mesh
          filename="package://urdf_assem_final/meshes/base_link.STL" />
      </geometry>
      <material
        name="">
        <color
          rgba="0.898039215686275 0.917647058823529 0.929411764705882 1" />
      </material>
    </visual>
    <collision>
      <origin
        xyz="0 0 0"
        rpy="0 0 0" />
      <geometry>
        <mesh
          filename="package://urdf_assem_final/meshes/base_link.STL" />
      </geometry>
    </collision>
  </link>
  <link
    name="wheel_l_link">
    <inertial>
      <origin
        xyz="2.2384368820183E-06 -0.00167135697643017 1.60704017726498E-06"
        rpy="0 0 0" />
      <mass
        value="4.80902409600041" />
      <inertia
        ixx="0.0226570934119946"
        ixy="-8.36535029894673E-08"
        ixz="-3.53132034618592E-09"
        iyy="0.0333153287221764"
        iyz="-5.9900188467449E-08"
        izz="0.0226570945548089" />
    </inertial>
    <visual>
      <origin
        xyz="0 0 0"
        rpy="0 0 0" />
      <geometry>
        <mesh
          filename="package://urdf_assem_final/meshes/wheel_l_link.STL" />
      </geometry>
      <material
        name="">
        <color
          rgba="0.298039215686275 0.298039215686275 0.298039215686275 1" />
      </material>
    </visual>
    <collision>
      <origin
        xyz="0 0 0"
        rpy="0 0 0" />
      <geometry>
        <mesh
          filename="package://urdf_assem_final/meshes/wheel_l_link.STL" />
      </geometry>
    </collision>
  </link>
  <joint
    name="l_joint"
    type="continuous">
    <origin
      xyz="0 -0.24448 0.00035754"
      rpy="0 0.16066 0" />
    <parent
      link="base_link" />
    <child
      link="wheel_l_link" />
    <axis
      xyz="0 -1 0" />
  </joint>
  <link
    name="wheel_r_Link">
    <inertial>
      <origin
        xyz="-2.7412767007462E-06 0.00244295553961049 2.80321530321537E-07"
        rpy="0 0 0" />
      <mass
        value="4.80902409600043" />
      <inertia
        ixx="0.0226570906467723"
        ixy="-1.02367159462644E-07"
        ixz="1.28981896897648E-09"
        iyy="0.0333153287221767"
        iyz="1.03396899017987E-08"
        izz="0.0226570973200315" />
    </inertial>
    <visual>
      <origin
        xyz="0 0 0"
        rpy="0 0 0" />
      <geometry>
        <mesh
          filename="package://urdf_assem_final/meshes/wheel_r_Link.STL" />
      </geometry>
      <material
        name="">
        <color
          rgba="0.298039215686275 0.298039215686275 0.298039215686275 1" />
      </material>
    </visual>
    <collision>
      <origin
        xyz="0 0 0"
        rpy="0 0 0" />
      <geometry>
        <mesh
          filename="package://urdf_assem_final/meshes/wheel_r_Link.STL" />
      </geometry>
    </collision>
  </link>
  <joint
    name="r_joint"
    type="continuous">
    <origin
      xyz="0 0.24348 0.00035754"
      rpy="0 0.16066 0" />
    <parent
      link="base_link" />
    <child
      link="wheel_r_Link" />
    <axis
      xyz="0 1 0" />
  </joint>
  <link
    name="lidar_real_Link">
    <inertial>
      <origin
        xyz="0.0119831298968675 0.000257383050308535 0.00148462283570416"
        rpy="0 0 0" />
      <mass
        value="1.45459502470387" />
      <inertia
        ixx="0.00125076189791548"
        ixy="-1.98466416096909E-05"
        ixz="-0.000186492107347762"
        iyy="0.00216267675002536"
        iyz="-2.53727203492436E-06"
        izz="0.00257032328598136" />
    </inertial>
    <visual>
      <origin
        xyz="0 0 0"
        rpy="0 0 0" />
      <geometry>
        <mesh
          filename="package://urdf_assem_final/meshes/lidar_real_Link.STL" />
      </geometry>
      <material
        name="">
        <color
          rgba="0.752941176470588 0.752941176470588 0.752941176470588 1" />
      </material>
    </visual>
    <collision>
      <origin
        xyz="0 0 0"
        rpy="0 0 0" />
      <geometry>
        <mesh
          filename="package://urdf_assem_final/meshes/lidar_real_Link.STL" />
      </geometry>
    </collision>
  </link>
  <joint
    name="lidar_joint"
    type="continuous">
    <origin
      xyz="-0.002469 -5.2666E-05 0.38249"
      rpy="0 0.16066 0" />
    <parent
      link="base_link" />
    <child
      link="lidar_real_Link" />
    <axis
      xyz="-0.15997 0 0.98712" />
  </joint>
</robot>